Workbook
Name Branch_name: [1]Sheet1!$D$2:$D$186
Name budget_branch: Table1[UNIT NAME]
Name budget_branch: Table1[UNIT NAME]
Name budget_branch: Table1[UNIT NAME]
Name budget_branch: Table1[UNIT NAME]
Name budget_branch: Table1[UNIT NAME]
Name RNG_STUDENT_CATEGORY: CATEGORY!$C$11:$D$15

Sheet Category Wise Data
A3: Category | B3: Category Range | C3: UNIT NAME | D3: Count of UNIT NAME | E3: ` | F3: Category | G3: Category Range | H3: Count of UNIT NAME
A4: Micro | B4: 1 to 500 | C4: Aligarh | D4: 1 | F4: Micro | G4: 1 to 500 | H4: 72
C5: Anand | D5: 1 | F5: Small | G5: 501 to 1000 | H5: 62
C6: Asansol | D6: 1 | F6: Medium | G6: 1001 to 2500 | H6: 27
C7: Bahadurgarh | D7: 1 | F7: Large | G7: 2501 to 5000 | H7: 16
C8: Belgaum | D8: 1 | F8: Mega | G8: 5000> | H8: 9
C9: Bellary | D9: 1 | F9: Grand Total | H9: 186
C10: Bhagalpur | D10: 1
C11: Bharatpur | D11: 1
C12: Bharuch | D12: 1
C13: Bhiwadi | D13: 1
C14: Bhuj | D14: 1
C15: Bilaspur | D15: 1
C16: Brahmapur | D16: 1
C17: Bulandshahr | D17: 1
C18: Churu | D18: 1
C19: Cuttack | D19: 1
C20: Darbhanga | D20: 1
C21: Dhule | D21: 1
... C75: Yamunanagar | D75: 1
B76: 1 to 500 Total | D76: 72
A77: Micro Total | D77: 72
A78: Small | B78: 501 to 1000 | C78: Ahmednagar | D78: 1
C79: Ajmer | D79: 1
C80: Akola | D80: 1
C81: Allahabad | D81: 1
C82: Alleppey | D82: 1
C83: Alwar | D83: 1
C84: Ambala | D84: 1
C85: Amravati | D85: 1
C86: Anantapur | D86: 1
C87: Bareilly | D87: 1
C88: Beawar | D88: 1
C89: Bhavnagar | D89: 1
C90: Bhilai | D90: 1
... C139: West Godavari | D139: 1
B140: 501 to 1000 Total | D140: 62
A141: Small Total | D141: 62
A142: Medium | B142: 1001 to 2500 | C142: Agra | D142: 1
C143: Amritsar | D143: 1
...

Sheet DATA 2026-27
A1: REGION | B1: UNIT NAME | C1: STATE | D1: TYPE | E1: IS STUDENT ASSO | F1: MEMBER COUNT | G1: STUDENT COUNT | H1: OWNED/RENTED | I1: SET UP DATE | J1: Category BRC | K1: Category Range BRC | L1: CATEGORY OF STUDENT ASSO | M1: CATEGORY RANGE BSA
A2: CIRC | B2: CIRC | C2: Uttar Pradesh | D2: RC | E2: YES | F2: 14374 | G2: 69857 | H2: Owned
A3: CIRC | B3: Agra | C3: Uttar Pradesh | D3: Branch | E3: YES | F3: 1880 | G3: 5012 | H3: Owned | I3: 29418 | J3: Medium | K3: 1001 to 2500 | L3: =VLOOKUP(Table1[[#This Row],[STUDENT COUNT]],RNG_STUDENT_CATEGORY,2,TRUE) -> Large | M3: =_xlfn.XLOOKUP(Table1[[#This Row],[CATEGORY OF STUDENT ASSO]],CATEGORY!$D$11:$D$15,CATEGORY!$B$11:$B$15) -> 5001 to 10000
A4: CIRC | B4: Ajmer | C4: Rajasthan | D4: Branch | E4: YES | F4: 881 | G4: 1870 | H4: Owned | I4: 33147 | J4: Small | K4: 501 to 1000 | L4: =VLOOKUP(Table1[[#This Row],[STUDENT COUNT]],RNG_STUDENT_CATEGORY,2,TRUE) -> Small | M4: =_xlfn.XLOOKUP(Table1[[#This Row],[CATEGORY OF STUDENT ASSO]],CATEGORY!$D$11:$D$15,CATEGORY!$B$11:$B$15) -> 10001 to 3000
A5: CIRC | B5: Aligarh | C5: Uttar Pradesh | D5: Branch | E5: YES | F5: 418 | G5: 1947 | H5: Rented | I5: 39438 | J5: Micro | K5: 1 to 500 | L5: =VLOOKUP(Table1[[#This Row],[STUDENT COUNT]],RNG_STUDENT_CATEGORY,2,TRUE) -> Small | M5: =_xlfn.XLOOKUP(Table1[[#This Row],[CATEGORY OF STUDENT ASSO]],CATEGORY!$D$11:$D$15,CATEGORY!$B$11:$B$15) -> 10001 to 3000
A6: CIRC | B6: Allahabad | C6: Uttar Pradesh | D6: Branch | E6: YES | F6: 608 | G6: 3395 | H6: Owned | I6: 31240 | J6: Small | K6: 501 to 1000 | L6: =VLOOKUP(Table1[[#This Row],[STUDENT COUNT]],RNG_STUDENT_CATEGORY,2,TRUE) -> Medium | M6: =_xlfn.XLOOKUP(Table1[[#This Row],[CATEGORY OF STUDENT ASSO]],CATEGORY!$D$11:$D$15,CATEGORY!$B$11:$B$15) -> 3001 to 5000
A7: CIRC | B7: Alwar | C7: Rajasthan | D7: Branch | E7: YES | F7: 886 | G7: 1896 | H7: Owned | I7: 32578 | J7: Small | K7: 501 to 1000 | L7: =VLOOKUP(Table1[[#This Row],[STUDENT COUNT]],RNG_STUDENT_CATEGORY,2,TRUE) -> Small | M7: =_xlfn.XLOOKUP(Table1[[#This Row],[CATEGORY OF STUDENT ASSO]],CATEGORY!$D$11:$D$15,CATEGORY!$B$11:$B$15) -> 10001 to 3000
A8: CIRC | B8: Bareilly | C8: Uttar Pradesh | D8: Branch | E8: YES | F8: 638 | G8: 1816 | H8: Owned | I8: 32365 | J8: Small | K8: 501 to 1000 | L8: =VLOOKUP(Table1[[#This Row],[STUDENT COUNT]],RNG_STUDENT_CATEGORY,2,TRUE) -> Small | M8: =_xlfn.XLOOKUP(Table1[[#This Row],[CATEGORY OF STUDENT ASSO]],CATEGORY!$D$11:$D$15,CATEGORY!$B$11:$B$15) -> 10001 to 3000
A9: CIRC | B9: Beawar | C9: Rajasthan | D9: Branch | E9: YES | F9: 609 | G9: 1321 | H9: Owned | I9: 39726 | J9: Small | K9: 501 to 1000 | L9: =VLOOKUP(Table1[[#This Row],[STUDENT COUNT]],RNG_STUDENT_CATEGORY,2,TRUE) -> Small | M9: =_xlfn.XLOOKUP(Table1[[#This Row],[CATEGORY OF STUDENT ASSO]],CATEGORY!$D$11:$D$15,CATEGORY!$B$11:$B$15) -> 10001 to 3000
A10: CIRC | B10: Bharatpur | C10: Rajasthan | D10: Branch | E10: YES | F10: 314 | G10: 619 | H10: Rented | I10: 41680 | J10: Micro | K10: 1 to 500 | L10: =VLOOKUP(Table1[[#This Row],[STUDENT COUNT]],RNG_STUDENT_CATEGORY,2,TRUE) -> Micro | M10: =_xlfn.XLOOKUP(Table1[[#This Row],[CATEGORY OF STUDENT ASSO]],CATEGORY!$D$11:$D$15,CATEGORY!$B$11:$B$15) -> 1 to 1000
A11: CIRC | B11: Bhilai | C11: Chattisgarh | D11: Branch | E11: YES | F11: 836 | G11: 3239 | H11: Owned | I11: 37012 | J11: Small | K11: 501 to 1000 | L11: =VLOOKUP(Table1[[#This Row],[STUDENT COUNT]],RNG_STUDENT_CATEGORY,2,TRUE) -> Medium | M11: =_xlfn.XLOOKUP(Table1[[#This Row],[CATEGORY OF STUDENT ASSO]],CATEGORY!$D$11:$D$15,CATEGORY!$B$11:$B$15) -> 3001 to 5000
A12: CIRC | B12: Bhilwara | C12: Rajasthan | D12: Branch | E12: YES | F12: 1710 | G12: 3633 | H12: Owned | I12: 32142 | J12: Medium | K12: 1001 to 2500 | L12: =VLOOKUP(Table1[[#This Row],[STUDENT COUNT]],RNG_STUDENT_CATEGORY,2,TRUE) -> Medium | M12: =_xlfn.XLOOKUP(Table1[[#This Row],[CATEGORY OF STUDENT ASSO]],CATEGORY!$D$11:$D$15,CATEGORY!$B$11:$B$15) -> 3001 to 5000
A13: CIRC | B13: Bhopal | C13: Madhya Pradesh | D13: Branch | E13: YES | F13: 2129 | G13: 5269 | H13: Owned | I13: 29571 | J13: Medium | K13: 1001 to 2500 | L13: =VLOOKUP(Table1[[#This Row],[STUDENT COUNT]],RNG_STUDENT_CATEGORY,2,TRUE) -> Large | M13: =_xlfn.XLOOKUP(Table1[[#This Row],[CATEGORY OF STUDENT ASSO]],CATEGORY!$D$11:$D$15,CATEGORY!$B$11:$B$15) -> 5001 to 10000
A14: CIRC | B14: Bikaner | C14: Rajasthan | D14: Branch | E14: YES | F14: 890 | G14: 2469 | H14: Owned | I14: 38541 | J14: Small | K14: 501 to 1000 | L14: =VLOOKUP(Table1[[#This Row],[STUDENT COUNT]],RNG_STUDENT_CATEGORY,2,TRUE) -> Small | M14: =_xlfn.XLOOKUP(Table1[[#This Row],[CATEGORY OF STUDENT ASSO]],CATEGORY!$D$11:$D$15,CATEGORY!$B$11:$B$15) -> 10001 to 3000
... A16: CIRC | B16: Chittorgarh | C16: Rajasthan | D16: Branch | E16: YES | F16: 566 | G16: 1691 | H16: Rented | I16: 41359 | J16: Small | K16: 501 to 1000 | L16: =VLOOKUP(Table1[[#This Row],[STUDENT COUNT]],RNG_STUDENT_CATEGORY,2,TRUE) -> Small | M16: =_xlfn.XLOOKUP(Table1[[#This Row],[CATEGORY OF STUDENT ASSO]],CATEGORY!$D$11:$D$15,CATEGORY!$B$11:$B$15) -> 10001 to 3000
A17: CIRC | B17: Dehradun | C17: Uttarakhand | D17: Branch | E17: NO | F17: 1001 | G17: 2701 | H17: Owned | I17: 32263 | J17: Medium | K17: 1001 to 2500
A18: CIRC | B18: Dhanbad | C18: Jharkhand | D18: Branch | E18: YES | F18: 640 | G18: 2283 | H18: Owned | I18: 32862 | J18: Small | K18: 501 to 1000 | L18: =VLOOKUP(Table1[[#This Row],[STUDENT COUNT]],RNG_STUDENT_CATEGORY,2,TRUE) -> Small | M18: =_xlfn.XLOOKUP(Table1[[#This Row],[CATEGORY OF STUDENT ASSO]],CATEGORY!$D$11:$D$15,CATEGORY!$B$11:$B$15) -> 10001 to 3000
A19: CIRC | B19: Ghaziabad | C19: Uttar Pradesh | D19: Branch | E19: YES | F19: 4798 | G19: 11176 | H19: Owned | I19: 27583 | J19: Large | K19: 2501 to 5000 | L19: =VLOOKUP(Table1[[#This Row],[STUDENT COUNT]],RNG_STUDENT_CATEGORY,2,TRUE) -> Mega | M19: =_xlfn.XLOOKUP(Table1[[#This Row],[CATEGORY OF STUDENT ASSO]],CATEGORY!$D$11:$D$15,CATEGORY!$B$11:$B$15) -> >10000
A20: CIRC | B20: Gorakhpur | C20: Uttar Pradesh | D20: Branch | E20: YES | F20: 601 | G20: 3780 | H20: Rented | I20: 38968 | J20: Small | K20: 501 to 1000 | L20: =VLOOKUP(Table1[[#This Row],[STUDENT COUNT]],RNG_STUDENT_CATEGORY,2,TRUE) -> Medium | M20: =_xlfn.XLOOKUP(Table1[[#This Row],[CATEGORY OF STUDENT ASSO]],CATEGORY!$D$11:$D$15,CATEGORY!$B$11:$B$15) -> 3001 to 5000
A21: CIRC | B21: Gwalior | C21: Madhya Pradesh | D21: Branch | E21: YES | F21: 694 | G21: 2169 | H21: Owned | I21: 32037 | J21: Small | K21: 501 to 1000 | L21: =VLOOKUP(Table1[[#This Row],[STUDENT COUNT]],RNG_STUDENT_CATEGORY,2,TRUE) -> Small | M21: =_xlfn.XLOOKUP(Table1[[#This Row],[CATEGORY OF STUDENT ASSO]],CATEGORY!$D$11:$D$15,CATEGORY!$B$11:$B$15) -> 10001 to 3000
A22: CIRC | B22: Indore | C22: Madhya Pradesh | D22: Branch | E22: YES | F22: 5259 | G22: 11765 | H22: Owned | I22: 26163 | J22: Mega | K22: 5000> | L22: =VLOOKUP(Table1[[#This Row],[STUDENT COUNT]],RNG_STUDENT_CATEGORY,2,TRUE) -> Mega | M22: =_xlfn.XLOOKUP(Table1[[#This Row],[CATEGORY OF STUDENT ASSO]],CATEGORY!$D$11:$D$15,CATEGORY!$B$11:$B$15) -> >10000
A23: CIRC | B23: Jabalpur | C23: Madhya Pradesh | D23: Branch | E23: YES | F23: 739 | G23: 2432 | H23: Rented | I23: 38095 | J23: Small | K23: 501 to 1000 | L23: =VLOOKUP(Table1[[#This Row],[STUDENT COUNT]],RNG_STUDENT_CATEGORY,2,TRUE) -> Small | M23: =_xlfn.XLOOKUP(Table1[[#This Row],[CATEGORY OF STUDENT ASSO]],CATEGORY!$D$11:$D$15,CATEGORY!$B$11:$B$15) -> 10001 to 3000
A24: CIRC | B24: Jaipur | C24: Rajasthan | D24: Branch | E24: YES | F24: 11687 | G24: 19498 | H24: Owned | I24: 25659 | J24: Mega | K24: 5000> | L24: =VLOOKUP(Table1[[#This Row],[STUDENT COUNT]],RNG_STUDENT_CATEGORY,2,TRUE) -> Mega | M24: =_xlfn.XLOOKUP(Table1[[#This Row],[CATEGORY OF STUDENT ASSO]],CATEGORY!$D$11:$D$15,CATEGORY!$B$11:$B$15) -> >10000
A25: CIRC | B25: Jamshedpur | C25: Jharkhand | D25: Branch | E25: YES | F25: 852 | G25: 2820 | H25: Rented | I25: 26163 | J25: Small | K25: 501 to 1000 | L25: =VLOOKUP(Table1[[#This Row],[STUDENT COUNT]],RNG_STUDENT_CATEGORY,2,TRUE) -> Small | M25: =_xlfn.XLOOKUP(Table1[[#This Row],[CATEGORY OF STUDENT ASSO]],CATEGORY!$D$11:$D$15,CATEGORY!$B$11:$B$15) -> 10001 to 3000
A26: CIRC | B26: Jhansi | C26: Uttar Pradesh | D26: Branch | E26: YES | F26: 360 | G26: 1467 | H26: Rented | I26: 41359 | J26: Micro | K26: 1 to 500 | L26: =VLOOKUP(Table1[[#This Row],[STUDENT COUNT]],RNG_STUDENT_CATEGORY,2,TRUE) -> Small | M26: =_xlfn.XLOOKUP(Table1[[#This Row],[CATEGORY OF STUDENT ASSO]],CATEGORY!$D$11:$D$15,CATEGORY!$B$11:$B$15) -> 10001 to 3000
A27: CIRC | B27: Jodhpur | C27: Rajasthan | D27: Branch | E27: YES | F27: 2574 | G27: 5208 | H27: Owned | I27: 28019 | J27: Large | K27: 2501 to 5000 | L27: =VLOOKUP(Table1[[#This Row],[STUDENT COUNT]],RNG_STUDENT_CATEGORY,2,TRUE) -> Large | M27: =_xlfn.XLOOKUP(Table1[[#This Row],[CATEGORY OF STUDENT ASSO]],CATEGORY!$D$11:$D$15,CATEGORY!$B$11:$B$15) -> 5001 to 10000
A28: CIRC | B28: Kishangarh | C28: Rajasthan | D28: Branch | E28: YES | F28: 517 | G28: 1002 | H28: Owned | I28: 41359 | J28: Small | K28: 501 to 1000 | L28: =VLOOKUP(Table1[[#This Row],[STUDENT COUNT]],RNG_STUDENT_CATEGORY,2,TRUE) -> Small | M28: =_xlfn.XLOOKUP(Table1[[#This Row],[CATEGORY OF STUDENT ASSO]],CATEGORY!$D$11:$D$15,CATEGORY!$B$11:$B$15) -> 10001 to 3000
A29: CIRC | B29: Kota | C29: Rajasthan | D29: Branch | E29: YES | F29: 1872 | G29: 4094 | H29: Owned | I29: 31306 | J29: Medium | K29: 1001 to 2500 | L29: =VLOOKUP(Table1[[#This Row],[STUDENT COUNT]],RNG_STUDENT_CATEGORY,2,TRUE) -> Medium | M29: =_xlfn.XLOOKUP(Table1[[#This Row],[CATEGORY OF STUDENT ASSO]],CATEGORY!$D$11:$D$15,CATEGORY!$B$11:$B$15) -> 3001 to 5000
... A46: CIRC | B46: Varanasi | C46: Uttar Pradesh | D46: Branch | E46: YES | F46: 924 | G46: 4064 | H46: Owned | I46: 32494 | J46: Small | K46: 501 to 1000 | L46: =VLOOKUP(Table1[[#This Row],[STUDENT COUNT]],RNG_STUDENT_CATEGORY,2,TRUE) -> Medium | M46: =_xlfn.XLOOKUP(Table1[[#This Row],[CATEGORY OF STUDENT ASSO]],CATEGORY!$D$11:$D$15,CATEGORY!$B$11:$B$15) -> 3001 to 5000
A47: CIRC | B47: Haridwar | C47: Uttarakhand | D47: Branch | E47: NO | F47: 451 | G47: 1807 | H47: Rented | I47: 42045 | J47: Micro | K47: 1 to 500
A48: CIRC | B48: Haldwani | C48: Uttarakhand | D48: Branch | E48: NO | F48: 414 | G48: 1611 | H48: Rented | I48: 42045 | J48: Micro | K48: 1 to 500
A49: CIRC | B49: Bulandshahr | C49: Uttar Pradesh | D49: Branch | E49: NO | F49: 263 | G49: 1335 | H49: Rented | I49: 43181 | J49: Micro | K49: 1 to 500
A50: CIRC | B50: Bhagalpur | C50: Bihar | D50: Branch | E50: NO | F50: 332 | G50: 1883 | H50: Rented | I50: 44700 | J50: Micro | K50: 1 to 500
A51: CIRC | B51: Hanumangarh | C51: Rajasthan | D51: Branch | E51: NO | F51: 292 | G51: 737 | H51: Rented | I51: 44701 | J51: Micro | K51: 1 to 500
A52: CIRC | B52: Satna | C52: Madhya Pradesh | D52: Branch | E52: NO | F52: 249 | G52: 1040 | H52: Rented | I52: 44944 | J52: Micro | K52: 1 to 500
A53: CIRC | B53: Mandsaur | C53: Madhya Pradesh | D53: Branch | E53: NO | F53: 273 | G53: 844 | H53: Rented | I53: 45152 | J53: Micro | K53: 1 to 500
A54: CIRC | B54: Rajsamand | C54: Rajasthan | D54: Branch | E54: NO | F54: 286 | G54: 898 | H54: Rented | I54: 45152 | J54: Micro | K54: 1 to 500
A55: CIRC | B55: Darbhanga | C55: Bihar | D55: Branch | E55: NO | F55: 296 | G55: 2988 | H55: Rented | I55: 45294 | J55: Micro | K55: 1 to 500
A56: CIRC | B56: Neemuch | C56: Madhya Pradesh | D56: Branch | E56: NO | F56: 293 | G56: 830 | H56: Rented | I56: 45294 | J56: Micro | K56: 1 to 500
A57: CIRC | B57: Muzaffarpur | C57: Bihar | D57: Branch | E57: NO | F57: 241 | G57: 1661 | H57: Rented | I57: 45294 | J57: Micro | K57: 1 to 500
...

Sheet SUMMARY
A3: REGION | B3: OLDEST BRANCH | C3: OLDEST DATE | D3: NEWEST BRANCH | E3: NEWEST DATE
A4: CIRC | B4: Jaipur | C4: 25659 | D4: Korba | E4: 46059
A5: EIRC | B5: Asansol | C5: 27282 | D5: Brahmapur | E5: 42630
A6: NIRC | B6: Chandigarh | C6: 26999 | D6: Mandi Gobind Garh | E6: 45152
A7: SIRC | B7: Bangalore, Coimbatore, Hyderabad, Madurai | C7: 22737 | D7: Khammam, Nizamabad | E7: 45804
A8: WIRC | B8: Ahmedabad, Pune | C8: 22737 | D8: Morbi District | E8: 45938
A11: REGION | B11: COUNT OF MEMBER | C11: COUNT OF STUDENTS | D11: NO OF BRANCHES
A12: CIRC | B12: 86892 | C12: 263955 | D12: 62
A13: EIRC | B13: 31029 | C13: 76410 | D13: 13
A14: NIRC | B14: 82172 | C14: 169992 | D14: 25
A15: SIRC | B15: 99023 | C15: 324085 | D15: 48
A16: WIRC | B16: 141379 | C16: 300005 | D16: 38
A17: Grand Total | B17: 440495 | C17: 1134447 | D17: 186
A19: Count of UNIT NAME | B19: Category
A20: REGION | B20: Micro | C20: Small | D20: Medium | E20: Large | F20: Mega | G20: Grand Total
A21: CIRC | B21: 25 | C21: 21 | D21: 10 | E21: 4 | F21: 2 | G21: 62
A22: EIRC | B22: 10 | C22: 1 | D22: 2 | G22: 13
A23: NIRC | B23: 7 | C23: 10 | D23: 4 | E23: 3 | F23: 1 | G23: 25
A24: SIRC | B24: 16 | C24: 19 | D24: 9 | E24: 2 | F24: 2 | G24: 48
A25: WIRC | B25: 14 | C25: 11 | D25: 2 | E25: 7 | F25: 4 | G25: 38
A26: Grand Total | B26: 72 | C26: 62 | D26: 27 | E26: 16 | F26: 9 | G26: 186
A30: Category | B30: UNIT NAME | C30: Count of UNIT NAME
A31: Micro | B31: Aligarh | C31: 1
B32: Anand | C32: 1
B33: Asansol | C33: 1
B34: Bahadurgarh | C34: 1
B35: Belgaum | C35: 1
B36: Bellary | C36: 1
B37: Bhagalpur | C37: 1
B38: Bharatpur | C38: 1
B39: Bharuch | C39: 1
B40: Bhiwadi | C40: 1
B41: Bhuj | C41: 1
B42: Bilaspur | C42: 1
B43: Brahmapur | C43: 1
... B102: Yamunanagar | C102: 1
A103: Micro Total | C103: 72
A104: Small | B104: Ahmednagar | C104: 1
B105: Ajmer | C105: 1
B106: Akola | C106: 1
...

Sheet Sheet11
A3: Boolean | B3: Name Of The Branch | C3: Date From Which Set Up | D3: Total Year | E3: Category | F3: Count
A4: FALSE | B4: AGRA | C4: 29418 | D4: 46 | E4: Medium | F4: 1
B5: AHMEDABAD | C5: 22737 | D5: 64 | E5: Mega | F5: 1
B6: AHMEDNAGAR / AHILYANAGAR | C6: 37513 | D6: 24 | E6: Small | F6: 1
B7: AJMER | C7: 33147 | D7: 36 | E7: Small | F7: 1
B8: AKOLA | C8: 37882 | D8: 23 | E8: Small | F8: 1
B9: ALIGARH | C9: 39438 | D9: 19 | E9: Micro | F9: 1
B10: ALLAHABAD / PRAYAGRAJ | C10: 31240 | D10: 41 | E10: Small | F10: 1
B11: ALLEPPEY / ALAPPUZHA | C11: 29846 | D11: 45 | E11: Small | F11: 1
B12: ALWAR | C12: 32578 | D12: 38 | E12: Small | F12: 1
B13: AMBALA | C13: 36612 | D13: 27 | E13: Small | F13: 1
B14: AMRAVATI | C14: 39534 | D14: 19 | E14: Small | F14: 1
B15: AMRITSAR | C15: 28749 | D15: 48 | E15: Medium | F15: 1
B16: ANAND | C16: 31505 | D16: 40 | E16: Micro | F16: 1
... B184: YAMUNANAGAR | C184: 31897 | D184: 39 | E184: Micro | F184: 1
A185: FALSE Total | F185: 181
A186: TRUE | B186: BHILAI | C186: 37012 | D186: 25 | E186: Small | F186: 1
B187: JAMNAGAR | C187: 37326 | D187: 25 | E187: Small | F187: 1
B188: JODHPUR | C188: 28019 | D188: 50 | E188: Large | F188: 1
B189: SONEPAT | C189: 37012 | D189: 25 | E189: Small | F189: 1
B190: UDUPI | C190: 37012 | D190: 25 | E190: Small | F190: 1
A191: TRUE Total | F191: 5
A192: Grand Total | F192: 186

Sheet NOTIFICATION DATE
A1: S.No. | B1: Region Wise S. No. | C1: Region | D1: Name Of The Branch | E1: Regulation | F1: Date From Which Set Up | G1: Notificatin No. | H1: Notification Date | I1: State | J1: Ac Branch | K1: Total Year | L1: Group by 25 | M1: Category | N1: New Branches | O1: A | P1: AA | S1: \b(CIRC|Agra|Ajmer|Aligarh|Allahabad|Alwar|Bareilly|Beawar|Bharatpur|Bhilai|Bhilwara|Bhopal|Bikaner|Bilaspur|Chittorgarh|Dehradun|Dhanbad|Ghaziabad|Gorakhpur|Gwalior|Indore|Jabalpur|Jaipur|Jamshedpur|Jhansi|Jodhpur|Kishangarh|Kota|Lucknow|Mathura|Meerut|Moradabad|Muzaffarnagar|Noida|Pali|Patna|Raipur|Ranchi|Ratlam|Saharanpur|Sikar|Sriganganagar|Udaipur|Ujjain|Varanasi|Haridwar|Haldwani|Bulandshahr|Bhagalpur|Hanumangarh|Satna|Mandsaur|Rajsamand|Darbhanga|Neemuch|Muzaffarpur|Raigarh|Tonk|Nagaur|Jhunjhunu|Churu|Bhiwadi|Korba|EIRC|Asansol|Bhubaneshwar|Cuttack|Dibrugarh|Durgapur|Guwahati|Raniganj|Rourkela|Sambalpur|Siliguri|Tinsukia|Jharsuguda|Brahmapur|NIRC|Amritsar|Chandigarh|Faridabad|Hisar|Jalandhar|Jammu|Ludhiana|Rohtak|Shimla|Karnal|Yamunanagar|Gurgaon|Panipat|Patiala|Ambala|Sangrur|Sonepat|Bathinda|Sirsa|Rewari|Bahadurgarh|Bhiwani|Kaithal|Kurukshetra|Mandi Gobind Garh|SIRC|Alleppey|Anantapur|Bangalore|Belgaum|Bellary|Calicut|Coimbatore|Ernakulum|Erode|Guntur|Hubli|Hyderabad|Kakinada|Kannur|Karimnagar|Kottayam|Kumbakonam|Kurnool|Madurai|Mangalore|Mysore|Nellore|Ongole|Palghat|Pondicherry|Quilon|Rajamahendravaram|Salem|Sivakasi|Tirunelveli|Tirupati|Thrissur|Tiruchirappalli|Tirupur|Trivandrum|Tuticorin|Udupi|Vellore|Vijayawada|Visakhapatnam|Warangal|West Godavari|Kalaburgi|Kanchipuram|Kadapa|Vizianagaram|Khammam |Nizamabad |WIRC|Ahmedabad|Ahmednagar|Akola|Amravati|Anand|Aurangabad|Baroda|Bharuch|Bhavnagar|Dhule|Gandhidham|Goa|Jalgaon|Jamnagar|Kolhapur|Latur|Nagpur|Nanded|Nashik|Navi Mumbai|Navsari|Pimpri Chinchwad|Pune|Rajkot|Ratnagiri|Sangali|Satara|Solapur|Surat|Thane|Vapi|Vasai|Bhuj|Kalyan|Inchakaranji|Gandhinagar|Gondia|Morbi District)\b
A2: =ROW()-1 -> 1 | B2: =COUNTIF($C$2:C2,C2) -> 1 | C2: Western Region | D2: AHMEDABAD | E2: Regulation 62-H(55) | F2: 22737 | G2: 1-CA(24)61 | H2: 22724 | I2: Gujarat | J2: AHMEDABAD | K2: =DATEDIF(F2,DATE(2027,3,31),"Y") -> 64 | L2: ="Greater Than "&FLOOR(K2,25) -> Greater Than 50 | M2: Mega | O2: =K2/25 -> 2.56 | P2: =MOD(O2,1)=0 -> FALSE
A3: =ROW()-1 -> 2 | B3: =COUNTIF($C$2:C3,C3) -> 2 | C3: Western Region | D3: PUNE | E3: Regulation 62-H(55) | F3: 22737 | G3: 1-CA(24)/61 | H3: 22724 | I3: Maharashtra | J3: PUNE | K3: =DATEDIF(F3,DATE(2027,3,31),"Y") -> 64 | L3: ="Greater Than "&FLOOR(K3,25) -> Greater Than 50 | M3: Mega | O3: =K3/25 -> 2.56 | P3: =MOD(O3,1)=0 -> FALSE
A4: =ROW()-1 -> 3 | B4: =COUNTIF($C$2:C4,C4) -> 3 | C4: Western Region | D4: BARODA / VADODARA | E4: 136(1) | F4: 24781 | G4: 1-CA(24)67 | H4: 24807 | I4: Gujarat | J4: BARODA | K4: =DATEDIF(F4,DATE(2027,3,31),"Y") -> 59 | L4: ="Greater Than "&FLOOR(K4,25) -> Greater Than 50 | M4: Large | O4: =K4/25 -> 2.36 | P4: =MOD(O4,1)=0 -> FALSE
A5: =ROW()-1 -> 4 | B5: =COUNTIF($C$2:C5,C5) -> 4 | C5: Western Region | D5: SURAT | E5: 136(1) | F5: 26163 | G5: 1-CA(42)/71 | H5: 26163 | I5: Gujarat | J5: SURAT | K5: =DATEDIF(F5,DATE(2027,3,31),"Y") -> 55 | L5: ="Greater Than "&FLOOR(K5,25) -> Greater Than 50 | M5: Mega | O5: =K5/25 -> 2.2 | P5: =MOD(O5,1)=0 -> FALSE
A6: =ROW()-1 -> 5 | B6: =COUNTIF($C$2:C6,C6) -> 5 | C6: Western Region | D6: GOA | E6: 136(1) | F6: 27164 | G6: 1-CA(67)/74 | H6: 27164 | I6: Goa | J6: GOA | K6: =DATEDIF(F6,DATE(2027,3,31),"Y") -> 52 | L6: ="Greater Than "&FLOOR(K6,25) -> Greater Than 50 | M6: Small | O6: =K6/25 -> 2.08 | P6: =MOD(O6,1)=0 -> FALSE
A7: =ROW()-1 -> 6 | B7: =COUNTIF($C$2:C7,C7) -> 6 | C7: Western Region | D7: RAJKOT | E7: 136(1) | F7: 28483 | G7: 28(RC)/1/7/77 | H7: 28509 | I7: Gujarat | J7: RAJKOT | K7: =DATEDIF(F7,DATE(2027,3,31),"Y") -> 49 | L7: ="Greater Than "&FLOOR(K7,25) -> Greater Than 25 | M7: Large | O7: =K7/25 -> 1.96 | P7: =MOD(O7,1)=0 -> FALSE
A8: =ROW()-1 -> 7 | B8: =COUNTIF($C$2:C8,C8) -> 7 | C8: Western Region | D8: NAGPUR | E8: 136(1) | F8: 28601 | G8: 28-(RC)/1/4/70 | H8: 28646 | I8: Maharashtra | J8: NAGPUR | K8: =DATEDIF(F8,DATE(2027,3,31),"Y") -> 48 | L8: ="Greater Than "&FLOOR(K8,25) -> Greater Than 25 | M8: Large | O8: =K8/25 -> 1.92 | P8: =MOD(O8,1)=0 -> FALSE
A9: =ROW()-1 -> 8 | B9: =COUNTIF($C$2:C9,C9) -> 8 | C9: Western Region | D9: KOLHAPUR | E9: 136(1) | F9: 29788 | G9: 28-RC(1)/8/81 | H9: 29795 | I9: Maharashtra | J9: KOLHAPUR | K9: =DATEDIF(F9,DATE(2027,3,31),"Y") -> 45 | L9: ="Greater Than "&FLOOR(K9,25) -> Greater Than 25 | M9: Small | O9: =K9/25 -> 1.8 | P9: =MOD(O9,1)=0 -> FALSE
A10: =ROW()-1 -> 9 | B10: =COUNTIF($C$2:C10,C10) -> 9 | C10: Western Region | D10: NASHIK | E10: 136(1) | F10: 29788 | G10: 28-RC((1)/9/81 | H10: 29795 | I10: Maharashtra | J10: NASHIK | K10: =DATEDIF(F10,DATE(2027,3,31),"Y") -> 45 | L10: ="Greater Than "&FLOOR(K10,25) -> Greater Than 25 | M10: Medium | O10: =K10/25 -> 1.8 | P10: =MOD(O10,1)=0 -> FALSE
A11: =ROW()-1 -> 10 | B11: =COUNTIF($C$2:C11,C11) -> 10 | C11: Western Region | D11: SOLAPUR | E11: 136(1) | F11: 31240 | G11: 28-RC(1)/10/85 | H11: 31264 | I11: Maharashtra | J11: SOLAPUR | K11: =DATEDIF(F11,DATE(2027,3,31),"Y") -> 41 | L11: ="Greater Than "&FLOOR(K11,25) -> Greater Than 25 | M11: Micro | O11: =K11/25 -> 1.64 | P11: =MOD(O11,1)=0 -> FALSE
A12: =ROW()-1 -> 11 | B12: =COUNTIF($C$2:C12,C12) -> 11 | C12: Western Region | D12: AURANGABAD / CHHATRAPATI SAMBHAJINAGAR | E12: 136(1) | F12: 31402 | G12: 28-RC(1)/11/86 | H12: 31432 | I12: Maharashtra | J12: AURANGABAD | K12: =DATEDIF(F12,DATE(2027,3,31),"Y") -> 41 | L12: ="Greater Than "&FLOOR(K12,25) -> Greater Than 25 | M12: Medium | O12: =K12/25 -> 1.64 | P12: =MOD(O12,1)=0 -> FALSE
A13: =ROW()-1 -> 12 | B13: =COUNTIF($C$2:C13,C13) -> 12 | C13: Western Region | D13: ANAND | E13: 136(1) | F13: 31505 | G13: 28-RC(1)/12/86 | H13: 31530 | I13: Gujarat | J13: ANAND | K13: =DATEDIF(F13,DATE(2027,3,31),"Y") -> 40 | L13: ="Greater Than "&FLOOR(K13,25) -> Greater Than 25 | M13: Micro | O13: =K13/25 -> 1.6 | P13: =MOD(O13,1)=0 -> FALSE
... A37: =ROW()-1 -> 36 | B37: =COUNTIF($C$2:C37,C37) -> 36 | C37: Western Region | D37: GANDHINAGAR | E37: 159(1) | F37: 45008 | G37: 1-CA(7)/(207)/2023 | H37: 45014 | I37: Gujarat | J37: GANDHINAGAR | K37: =DATEDIF(F37,DATE(2027,3,31),"Y") -> 4 | L37: ="Greater Than "&FLOOR(K37,25) -> Greater Than 0 | M37: Small | O37: =K37/25 -> 0.16 | P37: =MOD(O37,1)=0 -> FALSE
A38: =ROW()-1 -> 37 | B38: =COUNTIF($C$2:C38,C38) -> 37 | C38: Western Region | D38: GONDIA | E38: 159(1A) | F38: 45882 | G38: 1-CA(7)/(235)/2025 | H38: 45897 | I38: Maharashtra | J38: GONDIA | K38: =DATEDIF(F38,DATE(2027,3,31),"Y") -> 1 | L38: ="Greater Than "&FLOOR(K38,25) -> Greater Than 0 | M38: Micro | N38: New Branch | O38: =K38/25 -> 0.04 | P38: =MOD(O38,1)=0 -> FALSE
A39: =ROW()-1 -> 38 | B39: =COUNTIF($C$2:C39,C39) -> 38 | C39: Western Region | D39: MORBI | E39: 159(1A) | F39: 45938 | G39: 1-CA(7)/(238)/2025 | H39: 45965 | I39: Gujarat | J39: Morbi District | K39: =DATEDIF(F39,DATE(2027,3,31),"Y") -> 1 | L39: ="Greater Than "&FLOOR(K39,25) -> Greater Than 0 | M39: Micro | N39: New Branch | O39: =K39/25 -> 0.04 | P39: =MOD(O39,1)=0 -> FALSE
A40: =ROW()-1 -> 39 | B40: =COUNTIF($C$2:C40,C40) -> 1 | C40: Southern Region | D40: BANGALORE / BENGALURU | E40: Regulation 62-H(55) | F40: 22737 | G40: 1-CA(24)/61 | H40: 22724 | I40: Karnataka | J40: BANGALORE | K40: =DATEDIF(F40,DATE(2027,3,31),"Y") -> 64 | L40: ="Greater Than "&FLOOR(K40,25) -> Greater Than 50 | M40: Mega | O40: =K40/25 -> 2.56 | P40: =MOD(O40,1)=0 -> FALSE
A41: =ROW()-1 -> 40 | B41: =COUNTIF($C$2:C41,C41) -> 2 | C41: Southern Region | D41: COIMBATORE | E41: Regulation 62-H(55) | F41: 22737 | G41: 1-CA(24)/61 | H41: 22724 | I41: Tamil Nadu | J41: COIMBATORE | K41: =DATEDIF(F41,DATE(2027,3,31),"Y") -> 64 | L41: ="Greater Than "&FLOOR(K41,25) -> Greater Than 50 | M41: Medium | O41: =K41/25 -> 2.56 | P41: =MOD(O41,1)=0 -> FALSE
A42: =ROW()-1 -> 41 | B42: =COUNTIF($C$2:C42,C42) -> 3 | C42: Southern Region | D42: HYDERABAD | E42: Regulation 62-H(55) | F42: 22737 | G42: 1-CA(24)/61 | H42: 22724 | I42: Talangana | J42: HYDERABAD | K42: =DATEDIF(F42,DATE(2027,3,31),"Y") -> 64 | L42: ="Greater Than "&FLOOR(K42,25) -> Greater Than 50 | M42: Mega | O42: =K42/25 -> 2.56 | P42: =MOD(O42,1)=0 -> FALSE
A43: =ROW()-1 -> 42 | B43: =COUNTIF($C$2:C43,C43) -> 4 | C43: Southern Region | D43: MADURAI | E43: Regulation 62-H(55) | F43: 22737 | G43: 1-CA(24)/61 | H43: 22724 | I43: Tamil Nadu | J43: MADURAI | K43: =DATEDIF(F43,DATE(2027,3,31),"Y") -> 64 | L43: ="Greater Than "&FLOOR(K43,25) -> Greater Than 50 | M43: Small | O43: =K43/25 -> 2.56 | P43: =MOD(O43,1)=0 -> FALSE
A44: =ROW()-1 -> 43 | B44: =COUNTIF($C$2:C44,C44) -> 5 | C44: Southern Region | D44: ERNAKULAM | E44: 136(1) | F44: 24807 | G44: 1-CA(24)/67 | H44: 24782 | I44: Kerala | J44: Ernakulum | K44: =DATEDIF(F44,DATE(2027,3,31),"Y") -> 59 | L44: ="Greater Than "&FLOOR(K44,25) -> Greater Than 50 | M44: Large | O44: =K44/25 -> 2.36 | P44: =MOD(O44,1)=0 -> FALSE
A45: =ROW()-1 -> 44 | B45: =COUNTIF($C$2:C45,C45) -> 6 | C45: Southern Region | D45: MANGALORE / MANGALURU | E45: 136(1) | F45: 26163 | G45: 1-CA(42)/71 | H45: 26163 | I45: Karnataka | J45: MANGALORE | K45: =DATEDIF(F45,DATE(2027,3,31),"Y") -> 55 | L45: ="Greater Than "&FLOOR(K45,25) -> Greater Than 50 | M45: Medium | O45: =K45/25 -> 2.2 | P45: =MOD(O45,1)=0 -> FALSE
A46: =ROW()-1 -> 45 | B46: =COUNTIF($C$2:C46,C46) -> 7 | C46: Southern Region | D46: SALEM | E46: 136(1) | F46: 26163 | G46: 1-CA(42)/71 | H46: 26163 | I46: Tamil Nadu | J46: SALEM | K46: =DATEDIF(F46,DATE(2027,3,31),"Y") -> 55 | L46: ="Greater Than "&FLOOR(K46,25) -> Greater Than 50 | M46: Small | O46: =K46/25 -> 2.2 | P46: =MOD(O46,1)=0 -> FALSE
A47: =ROW()-1 -> 46 | B47: =COUNTIF($C$2:C47,C47) -> 8 | C47: Southern Region | D47: TIRUCHIRAPALLI | E47: 136(1) | F47: 26163 | G47: 1-CA(42)/71 | H47: 26163 | I47: Tamil Nadu | J47: Tiruchirappalli | K47: =DATEDIF(F47,DATE(2027,3,31),"Y") -> 55 | L47: ="Greater Than "&FLOOR(K47,25) -> Greater Than 50 | M47: Small | O47: =K47/25 -> 2.2 | P47: =MOD(O47,1)=0 -> FALSE
A48: =ROW()-1 -> 47 | B48: =COUNTIF($C$2:C48,C48) -> 9 | C48: Southern Region | D48: VIJAYAWADA | E48: 136(1) | F48: 26163 | G48: 1-CA(42)/71 | H48: 26163 | I48: Andhra Pradesh | J48: VIJAYAWADA | K48: =DATEDIF(F48,DATE(2027,3,31),"Y") -> 55 | L48: ="Greater Than "&FLOOR(K48,25) -> Greater Than 50 | M48: Medium | O48: =K48/25 -> 2.2 | P48: =MOD(O48,1)=0 -> FALSE
A49: =ROW()-1 -> 48 | B49: =COUNTIF($C$2:C49,C49) -> 10 | C49: Southern Region | D49: TRIVANDRUM / THIRUVANANTHAPURAM | E49: 136(1) | F49: 26323 | G49: 1-CA(50)/72 | H49: 26330 | I49: Kerala | J49: TRIVANDRUM | K49: =DATEDIF(F49,DATE(2027,3,31),"Y") -> 55 | L49: ="Greater Than "&FLOOR(K49,25) -> Greater Than 50 | M49: Medium | O49: =K49/25 -> 2.2 | P49: =MOD(O49,1)=0 -> FALSE
A50: =ROW()-1 -> 49 | B50: =COUNTIF($C$2:C50,C50) -> 11 | C50: Southern Region | D50: BELGAUM / BELAGAVI | E50: 136(1) | F50: 27190 | G50: 1-CA(69)/74 | H50: 27190 | I50: Karnataka | J50: BELGAUM | K50: =DATEDIF(F50,DATE(2027,3,31),"Y") -> 52 | L50: ="Greater Than "&FLOOR(K50,25) -> Greater Than 50 | M50: Micro | O50: =K50/25 -> 2.08 | P50: =MOD(O50,1)=0 -> FALSE
A51: =ROW()-1 -> 50 | B51: =COUNTIF($C$2:C51,C51) -> 12 | C51: Southern Region | D51: VISAKHAPATNAM | E51: 136(1) | F51: 28238 | G51: 1-CA(101)/77 | H51: 28256 | I51: Andhra Pradesh | J51: VISAKHAPATNAM | K51: =DATEDIF(F51,DATE(2027,3,31),"Y") -> 49 | L51: ="Greater Than "&FLOOR(K51,25) -> Greater Than 25 | M51: Medium | O51: =K51/25 -> 1.96 | P51: =MOD(O51,1)=0 -> FALSE
... A85: =ROW()-1 -> 84 | B85: =COUNTIF($C$2:C85,C85) -> 46 | C85: Southern Region | D85: VIZIANAGARAM | E85: 159(1A) | F85: 45518 | G85: 1-CA(7)/224/2024 | H85: 45524 | I85: Andhra Pradesh | J85: VIZIANAGARAM | K85: =DATEDIF(F85,DATE(2027,3,31),"Y") -> 2 | L85: ="Greater Than "&FLOOR(K85,25) -> Greater Than 0 | M85: Micro | O85: =K85/25 -> 0.08 | P85: =MOD(O85,1)=0 -> FALSE
A86: =ROW()-1 -> 85 | B86: =COUNTIF($C$2:C86,C86) -> 47 | C86: Southern Region | D86: KHAMMAM | E86: 159(1) | F86: 45804 | G86: 1-CA(7)/228/2025 | H86: 45814 | I86: Telangana | J86: Khammam | K86: =DATEDIF(F86,DATE(2027,3,31),"Y") -> 1 | L86: ="Greater Than "&FLOOR(K86,25) -> Greater Than 0 | M86: Micro | N86: New Branch | O86: =K86/25 -> 0.04 | P86: =MOD(O86,1)=0 -> FALSE
A87: =ROW()-1 -> 86 | B87: =COUNTIF($C$2:C87,C87) -> 48 | C87: Southern Region | D87: NIZAMABAD | E87: 159(1) | F87: 45804 | G87: 1-CA(7)/229/2025 | H87: 45814 | I87: Telangana | J87: Nizamabad | K87: =DATEDIF(F87,DATE(2027,3,31),"Y") -> 1 | L87: ="Greater Than "&FLOOR(K87,25) -> Greater Than 0 | M87: Micro | N87: New Branch | O87: =K87/25 -> 0.04 | P87: =MOD(O87,1)=0 -> FALSE
A88: =ROW()-1 -> 87 | B88: =COUNTIF($C$2:C88,C88) -> 1 | C88: Eastern Region | D88: ASANSOL | E88: 136(1) | F88: 27282 | G88: 1-CA(73)/74 | H88: 27289 | I88: West Bengal | J88: ASANSOL | K88: =DATEDIF(F88,DATE(2027,3,31),"Y") -> 52 | L88: ="Greater Than "&FLOOR(K88,25) -> Greater Than 50 | M88: Micro | O88: =K88/25 -> 2.08 | P88: =MOD(O88,1)=0 -> FALSE
A89: =ROW()-1 -> 88 | B89: =COUNTIF($C$2:C89,C89) -> 2 | C89: Eastern Region | D89: GUWAHATI | E89: 136(1) | F89: 28384 | G89: 28-RC(3)/3/77 | H89: 28420 | I89: Assam | J89: GUWAHATI | K89: =DATEDIF(F89,DATE(2027,3,31),"Y") -> 49 | L89: ="Greater Than "&FLOOR(K89,25) -> Greater Than 25 | M89: Medium | O89: =K89/25 -> 1.96 | P89: =MOD(O89,1)=0 -> FALSE
A90: =ROW()-1 -> 89 | B90: =COUNTIF($C$2:C90,C90) -> 3 | C90: Eastern Region | D90: BHUBANESWAR | E90: 136(1) | F90: 29114 | G90: 28-RC(3)/3/79 | H90: 29209 | I90: Odisha | J90: Bhubaneshwar | K90: =DATEDIF(F90,DATE(2027,3,31),"Y") -> 47 | L90: ="Greater Than "&FLOOR(K90,25) -> Greater Than 25 | M90: Medium | O90: =K90/25 -> 1.88 | P90: =MOD(O90,1)=0 -> FALSE
A91: =ROW()-1 -> 90 | B91: =COUNTIF($C$2:C91,C91) -> 4 | C91: Eastern Region | D91: CUTTACK | E91: 159(1) | F91: 32862 | G91: 28-RC(3)/4/90 | H91: 32911 | I91: Odisha | J91: CUTTACK | K91: =DATEDIF(F91,DATE(2027,3,31),"Y") -> 37 | L91: ="Greater Than "&FLOOR(K91,25) -> Greater Than 25 | M91: Micro | O91: =K91/25 -> 1.48 | P91: =MOD(O91,1)=0 -> FALSE
A92: =ROW()-1 -> 91 | B92: =COUNTIF($C$2:C92,C92) -> 5 | C92: Eastern Region | D92: DURGAPUR | E92: 159(1) | F92: 32940 | G92: 28-RC(3)/5/90 | H92: 32980 | I92: West Bengal | J92: DURGAPUR | K92: =DATEDIF(F92,DATE(2027,3,31),"Y") -> 37 | L92: ="Greater Than "&FLOOR(K92,25) -> Greater Than 25 | M92: Micro | O92: =K92/25 -> 1.48 | P92: =MOD(O92,1)=0 -> FALSE
A93: =ROW()-1 -> 92 | B93: =COUNTIF($C$2:C93,C93) -> 6 | C93: Eastern Region | D93: SILIGURI | E93: 159(1) | F93: 33147 | G93: 28-RC(3)/24/90 | H93: 33151 | I93: West Bengal | J93: SILIGURI | K93: =DATEDIF(F93,DATE(2027,3,31),"Y") -> 36 | L93: ="Greater Than "&FLOOR(K93,25) -> Greater Than 25 | M93: Small | O93: =K93/25 -> 1.44 | P93: =MOD(O93,1)=0 -> FALSE
A94: =ROW()-1 -> 93 | B94: =COUNTIF($C$2:C94,C94) -> 7 | C94: Eastern Region | D94: ROURKELA | E94: 159(1) | F94: 36144 | G94: 1-CA(7)/38/98 | H94: 36144 | I94: Odisha | J94: ROURKELA | K94: =DATEDIF(F94,DATE(2027,3,31),"Y") -> 28 | L94: ="Greater Than "&FLOOR(K94,25) -> Greater Than 25 | M94: Micro | O94: =K94/25 -> 1.12 | P94: =MOD(O94,1)=0 -> FALSE
A95: =ROW()-1 -> 94 | B95: =COUNTIF($C$2:C95,C95) -> 8 | C95: Eastern Region | D95: SAMBALPUR | E95: 159(1) | F95: 38842 | G95: 1-CA(7)/91/2006 | H95: 38868 | I95: Odisha | J95: SAMBALPUR | K95: =DATEDIF(F95,DATE(2027,3,31),"Y") -> 20 | L95: ="Greater Than "&FLOOR(K95,25) -> Greater Than 0 | M95: Micro | O95: =K95/25 -> 0.8 | P95: =MOD(O95,1)=0 -> FALSE
A96: =ROW()-1 -> 95 | B96: =COUNTIF($C$2:C96,C96) -> 9 | C96: Eastern Region | D96: DIBRUGARH | E96: 159(1A) | F96: 41642 | G96: 1-CA(7)/(157)2014 | H96: 41645 | I96: Assam | J96: DIBRUGARH | K96: =DATEDIF(F96,DATE(2027,3,31),"Y") -> 13 | L96: ="Greater Than "&FLOOR(K96,25) -> Greater Than 0 | M96: Micro | O96: =K96/25 -> 0.52 | P96: =MOD(O96,1)=0 -> FALSE
...

Sheet CATEGORY
B1: Criteria BRC | D1: Category as Branch(BRC)
B2: 1 to 500 | C2: 1 | D2: Micro
B3: 501 to 1000 | C3: 501 | D3: Small
B4: 1001 to 2500 | C4: 1001 | D4: Medium
B5: 2501 to 5000 | C5: 2501 | D5: Large
B6: 5000> | C6: 5001 | D6: Mega
B10: CRITERIA BSA | D10: CATEGORY OF BSA
B11: 1 to 1000 | C11: 1 | D11: Micro
B12: 10001 to 3000 | C12: 1001 | D12: Small
B13: 3001 to 5000 | C13: 3001 | D13: Medium
B14: 5001 to 10000 | C14: 5001 | D14: Large
B15: >10000 | C15: 10001 | D15: Mega

Sheet Mega
A3: Group by 25 | B3: Name Of The Branch | C3: Date From Which Set Up | D3: Total Year | E3: Category | F3: Count
A4: Greater Than 0 | B4: AHMEDNAGAR / AHILYANAGAR | C4: 37513 | D4: 23 | E4: Small | F4: 1
B5: AKOLA | C5: 37882 | D5: 22 | E5: Small | F5: 1
B6: ALIGARH | C6: 39438 | D6: 18 | E6: Micro | F6: 1
B7: AMRAVATI | C7: 39534 | D7: 18 | E7: Small | F7: 1
B8: ANANTAPUR | C8: 41720 | D8: 12 | E8: Small | F8: 1
B9: BAHADURGARH | C9: 42552 | D9: 9 | E9: Micro | F9: 1
B10: BEAWAR | C10: 39726 | D10: 17 | E10: Small | F10: 1
B11: BELLARY / BALLARI | C11: 38968 | D11: 19 | E11: Micro | F11: 1
B12: BHAGALPUR | C12: 44700 | D12: 3 | E12: Micro | F12: 1
B13: BHARATPUR | C13: 41680 | D13: 12 | E13: Micro | F13: 1
B14: BHARUCH | C14: 38968 | D14: 19 | E14: Micro | F14: 1
B15: BHAVNAGAR | C15: 40191 | D15: 16 | E15: Small | F15: 1
B16: BHILAI | C16: 37012 | D16: 24 | E16: Small | F16: 1
... B97: WEST GODAVARI | C97: 42230 | D97: 10 | E97: Small | F97: 1
A98: Greater Than 0 Total | F98: 94
A99: Greater Than 25 | B99: AGRA | C99: 29418 | D99: 45 | E99: Medium | F99: 1
B100: AJMER | C100: 33147 | D100: 35 | E100: Small | F100: 1
B101: ALLAHABAD / PRAYAGRAJ | C101: 31240 | D101: 40 | E101: Small | F101: 1
B102: ALLEPPEY / ALAPPUZHA | C102: 29846 | D102: 44 | E102: Small | F102: 1
B103: ALWAR | C103: 32578 | D103: 37 | E103: Small | F103: 1
B104: AMBALA | C104: 36612 | D104: 26 | E104: Small | F104: 1
B105: AMRITSAR | C105: 28749 | D105: 47 | E105: Medium | F105: 1
B106: ANAND | C106: 31505 | D106: 39 | E106: Micro | F106: 1
B107: AURANGABAD / CHHATRAPATI SAMBHAJINAGAR | C107: 31402 | D107: 40 | E107: Medium | F107: 1
B108: BAREILLY | C108: 32365 | D108: 37 | E108: Small | F108: 1
B109: BHATINDA | C109: 36612 | D109: 26 | E109: Medium | F109: 1
B110: BHILWARA | C110: 32142 | D110: 38 | E110: Medium | F110: 1
B111: BHOPAL | C111: 29571 | D111: 45 | E111: Medium | F111: 1
... B167: YAMUNANAGAR | C167: 31897 | D167: 38 | E167: Micro | F167: 1
A168: Greater Than 25 Total | F168: 69
A169: Greater Than 50 | B169: AHMEDABAD | C169: 22737 | D169: 64 | E169: Mega | F169: 1
B170: ASANSOL | C170: 27282 | D170: 51 | E170: Micro | F170: 1
B171: BANGALORE / BENGALURU | C171: 22737 | D171: 64 | E171: Mega | F171: 1
B172: BARODA / VADODARA | C172: 24781 | D172: 58 | E172: Large | F172: 1
B173: BELGAUM / BELAGAVI | C173: 27190 | D173: 51 | E173: Micro | F173: 1
B174: CHANDIGARH | C174: 26999 | D174: 52 | E174: Large | F174: 1
B175: COIMBATORE | C175: 22737 | D175: 64 | E175: Medium | F175: 1
B176: ERNAKULAM | C176: 24807 | D176: 58 | E176: Large | F176: 1
B177: GHAZIABAD | C177: 27583 | D177: 50 | E177: Large | F177: 1
...

Sheet LARGE
A3: Group by 25 | B3: Name Of The Branch | C3: Date From Which Set Up | D3: Total Year | E3: Category | F3: Count
A4: Greater Than 0 | B4: KALYAN DOMBIVLI | C4: 42386 | D4: 10 | E4: Large | F4: 1
B5: KANCHIPURAM / CHENGALPATTU | C5: 42230 | D5: 10 | E5: Large | F5: 1
B6: NAVI MUMBAI | C6: 38687 | D6: 20 | E6: Large | F6: 1
B7: PIMPRI CHINCHWAD | C7: 39534 | D7: 18 | E7: Large | F7: 1
B8: VASAI | C8: 38374 | D8: 21 | E8: Large | F8: 1
A9: Greater Than 0 Total | F9: 5
A10: Greater Than 25 | B10: FARIDABAD | C10: 29313 | D10: 45 | E10: Large | F10: 1
B11: JODHPUR | C11: 28019 | D11: 49 | E11: Large | F11: 1
B12: LUCKNOW | C12: 29418 | D12: 45 | E12: Large | F12: 1
B13: NAGPUR | C13: 28601 | D13: 47 | E13: Large | F13: 1
B14: NOIDA / GAUTAM BUDH NAGAR | C14: 33256 | D14: 35 | E14: Large | F14: 1
B15: RAJKOT | C15: 28483 | D15: 48 | E15: Large | F15: 1
A16: Greater Than 25 Total | F16: 6
A17: Greater Than 50 | B17: BARODA / VADODARA | C17: 24781 | D17: 58 | E17: Large | F17: 1
B18: CHANDIGARH | C18: 26999 | D18: 52 | E18: Large | F18: 1
B19: ERNAKULAM | C19: 24807 | D19: 58 | E19: Large | F19: 1
B20: GHAZIABAD | C20: 27583 | D20: 50 | E20: Large | F20: 1
B21: LUDHIANA | C21: 27282 | D21: 51 | E21: Large | F21: 1
A22: Greater Than 50 Total | F22: 5
A23: Grand Total | F23: 16

Sheet MEDIUM
A3: Group by 25 | B3: Name Of The Branch | C3: Date From Which Set Up | D3: Total Year | E3: Category | F3: Count
A4: Greater Than 0 | B4: TIRUPATHI | C4: 40191 | D4: 16 | E4: Medium | F4: 1
A5: Greater Than 0 Total | F5: 1
A6: Greater Than 25 | B6: AGRA | C6: 29418 | D6: 45 | E6: Medium | F6: 1
B7: AMRITSAR | C7: 28749 | D7: 47 | E7: Medium | F7: 1
B8: AURANGABAD / CHHATRAPATI SAMBHAJINAGAR | C8: 31402 | D8: 40 | E8: Medium | F8: 1
B9: BHATINDA | C9: 36612 | D9: 26 | E9: Medium | F9: 1
B10: BHILWARA | C10: 32142 | D10: 38 | E10: Medium | F10: 1
B11: BHOPAL | C11: 29571 | D11: 45 | E11: Medium | F11: 1
B12: BHUBANESWAR | C12: 29114 | D12: 46 | E12: Medium | F12: 1
B13: CALICUT/ KOZHIKODE | C13: 30015 | D13: 44 | E13: Medium | F13: 1
B14: DEHRADUN | C14: 32263 | D14: 37 | E14: Medium | F14: 1
B15: GUNTUR | C15: 29943 | D15: 44 | E15: Medium | F15: 1
B16: GUWAHATI | C16: 28384 | D16: 48 | E16: Medium | F16: 1
B17: HISAR | C17: 32365 | D17: 37 | E17: Medium | F17: 1
B18: JALANDHAR | C18: 29943 | D18: 44 | E18: Medium | F18: 1
... B27: VISAKHAPATNAM | C27: 28238 | D27: 48 | E27: Medium | F27: 1
A28: Greater Than 25 Total | F28: 22
A29: Greater Than 50 | B29: COIMBATORE | C29: 22737 | D29: 64 | E29: Medium | F29: 1
B30: MANGALORE / MANGALURU | C30: 26163 | D30: 54 | E30: Medium | F30: 1
B31: TRIVANDRUM / THIRUVANANTHAPURAM | C31: 26323 | D31: 54 | E31: Medium | F31: 1
B32: VIJAYAWADA | C32: 26163 | D32: 54 | E32: Medium | F32: 1
A33: Greater Than 50 Total | F33: 4
A34: Grand Total | F34: 27

Sheet SMALL
A3: Group by 25 | B3: Name Of The Branch | C3: Date From Which Set Up | D3: Total Year | E3: Category | F3: Count
A4: Greater Than 0 | B4: AHMEDNAGAR / AHILYANAGAR | C4: 37513 | D4: 23 | E4: Small | F4: 1
B5: AKOLA | C5: 37882 | D5: 22 | E5: Small | F5: 1
B6: AMRAVATI | C6: 39534 | D6: 18 | E6: Small | F6: 1
B7: ANANTAPUR | C7: 41720 | D7: 12 | E7: Small | F7: 1
B8: BEAWAR | C8: 39726 | D8: 17 | E8: Small | F8: 1
B9: BHAVNAGAR | C9: 40191 | D9: 16 | E9: Small | F9: 1
B10: BHILAI | C10: 37012 | D10: 24 | E10: Small | F10: 1
B11: BHIWANI | C11: 42552 | D11: 9 | E11: Small | F11: 1
B12: BIKANER | C12: 38541 | D12: 20 | E12: Small | F12: 1
B13: CHITTORGARH | C13: 41359 | D13: 13 | E13: Small | F13: 1
B14: GANDHIDHAM | C14: 40163 | D14: 16 | E14: Small | F14: 1
B15: GANDHINAGAR | C15: 45008 | D15: 3 | E15: Small | F15: 1
B16: GORAKHPUR | C16: 38968 | D16: 19 | E16: Small | F16: 1
... B36: WEST GODAVARI | C36: 42230 | D36: 10 | E36: Small | F36: 1
A37: Greater Than 0 Total | F37: 33
A38: Greater Than 25 | B38: AJMER | C38: 33147 | D38: 35 | E38: Small | F38: 1
B39: ALLAHABAD / PRAYAGRAJ | C39: 31240 | D39: 40 | E39: Small | F39: 1
B40: ALLEPPEY / ALAPPUZHA | C40: 29846 | D40: 44 | E40: Small | F40: 1
B41: ALWAR | C41: 32578 | D41: 37 | E41: Small | F41: 1
B42: AMBALA | C42: 36612 | D42: 26 | E42: Small | F42: 1
B43: BAREILLY | C43: 32365 | D43: 37 | E43: Small | F43: 1
B44: DHANBAD | C44: 32862 | D44: 36 | E44: Small | F44: 1
B45: GWALIOR | C45: 32037 | D45: 38 | E45: Small | F45: 1
B46: HIMACHAL PRADESH (SHIMLA) | C46: 32365 | D46: 37 | E46: Small | F46: 1
B47: JALGAON | C47: 31897 | D47: 38 | E47: Small | F47: 1
B48: JAMMU & KASHMIR | C48: 31976 | D48: 38 | E48: Small | F48: 1
B49: KOLHAPUR | C49: 29788 | D49: 44 | E49: Small | F49: 1
B50: KOTTAYAM | C50: 29705 | D50: 44 | E50: Small | F50: 1
... B61: VARANASI | C61: 32494 | D61: 37 | E61: Small | F61: 1
A62: Greater Than 25 Total | F62: 24
A63: Greater Than 50 | B63: GOA | C63: 27164 | D63: 51 | E63: Small | F63: 1
B64: JAMSHEDPUR | C64: 26163 | D64: 54 | E64: Small | F64: 1
B65: MADURAI | C65: 22737 | D65: 64 | E65: Small | F65: 1
B66: SALEM | C66: 26163 | D66: 54 | E66: Small | F66: 1
B67: TIRUCHIRAPALLI | C67: 26163 | D67: 54 | E67: Small | F67: 1
A68: Greater Than 50 Total | F68: 5
A69: Grand Total | F69: 62

Sheet MICRO
A3: Group by 25 | B3: Name Of The Branch | C3: Date From Which Set Up | D3: Total Year | E3: Category | F3: Count
A4: Greater Than 0 | B4: ALIGARH | C4: 39438 | D4: 18 | E4: Micro | F4: 1
B5: BAHADURGARH | C5: 42552 | D5: 9 | E5: Micro | F5: 1
B6: BELLARY / BALLARI | C6: 38968 | D6: 19 | E6: Micro | F6: 1
B7: BHAGALPUR | C7: 44700 | D7: 3 | E7: Micro | F7: 1
B8: BHARATPUR | C8: 41680 | D8: 12 | E8: Micro | F8: 1
B9: BHARUCH | C9: 38968 | D9: 19 | E9: Micro | F9: 1
B10: BHIWADI | C10: 45938 | D10: 0 | E10: Micro | F10: 1
B11: BHUJ | C11: 42215 | D11: 10 | E11: Micro | F11: 1
B12: BILASPUR | C12: 39073 | D12: 19 | E12: Micro | F12: 1
B13: BRAHMAPUR | C13: 42630 | D13: 9 | E13: Micro | F13: 1
B14: BULANDSHAHR | C14: 43181 | D14: 8 | E14: Micro | F14: 1
B15: CHURU | C15: 45839 | D15: 0 | E15: Micro | F15: 1
B16: DARBHANGA | C16: 45294 | D16: 2 | E16: Micro | F16: 1
... B57: WARANGAL | C57: 41642 | D57: 12 | E57: Micro | F57: 1
A58: Greater Than 0 Total | F58: 54
A59: Greater Than 25 | B59: ANAND | C59: 31505 | D59: 39 | E59: Micro | F59: 1
B60: CUTTACK | C60: 32862 | D60: 36 | E60: Micro | F60: 1
B61: DURGAPUR | C61: 32940 | D61: 36 | E61: Micro | F61: 1
B62: ERODE | C62: 31306 | D62: 40 | E62: Micro | F62: 1
B63: HUBLI / HUBBALLI | C63: 31306 | D63: 40 | E63: Micro | F63: 1
B64: KUMBAKONAM | C64: 29313 | D64: 45 | E64: Micro | F64: 1
B65: PONDICHERRY / PUDUCHERRY | C65: 31505 | D65: 39 | E65: Micro | F65: 1
B66: QUILON / KOLLAM | C66: 31976 | D66: 38 | E66: Micro | F66: 1
B67: ROURKELA | C67: 36144 | D67: 27 | E67: Micro | F67: 1
B68: SAHARANPUR | C68: 36612 | D68: 26 | E68: Micro | F68: 1
B69: SANGLI | C69: 31897 | D69: 38 | E69: Micro | F69: 1
B70: SOLAPUR | C70: 31240 | D70: 40 | E70: Micro | F70: 1
B71: TIRUNELVELI | C71: 29479 | D71: 45 | E71: Micro | F71: 1
... B74: YAMUNANAGAR | C74: 31897 | D74: 38 | E74: Micro | F74: 1
A75: Greater Than 25 Total | F75: 16
A76: Greater Than 50 | B76: ASANSOL | C76: 27282 | D76: 51 | E76: Micro | F76: 1
B77: BELGAUM / BELAGAVI | C77: 27190 | D77: 51 | E77: Micro | F77: 1
A78: Greater Than 50 Total | F78: 2
A79: Grand Total | F79: 72
